<?xml version="1.0" ?>
<!-- =================================================================================== -->
<!-- |    This document was autogenerated by xacro from robot.xacro                    | -->
<!-- |    EDITING THIS FILE BY HAND IS NOT RECOMMENDED                                 | -->
<!-- =================================================================================== -->
<robot name="bw">
  <!-- 定义"stick"（可能是辅助结构）的质量，值极小可能用于简化计算 -->
  <!-- 辅助结构长度：0.2米 -->
  <!-- 小腿长度：0.213米 -->
  <!-- 髋关节在Z轴的位置偏移：0米（无偏移） -->
  <!-- 大腿在Z轴的位置偏移：0米 -->
  <!-- 小腿在Z轴的位置偏移：-0.213米（向下方向） -->
  <!-- 小腿在Z轴的位置偏移：-0.213米（向下方向） -->
  <!-- 足端轮毂电机最大扭矩 -->
  <!-- 躯干绕Z轴的转动惯量：0.07576 kg·m²（原0.107） -->
  <!-- 髋关节绕Z轴的转动惯量：0.000440 kg·m² -->
  <!-- 大腿绕Z轴的转动惯量：0.000722 kg·m² -->
  <!-- 小腿绕Z轴的转动惯量：3.165E-05 kg·m² (原2.11E-05×1.5) -->
  <!-- 小腿绕Z轴的转动惯量： -->
  <material name="black">
    <color rgba="0.0 0.0 0.0 1.0"/>
  </material>
  <material name="blue">
    <color rgba="0.0 0.0 0.8 1.0"/>
  </material>
  <material name="green">
    <color rgba="0.0 0.8 0.0 1.0"/>
  </material>
  <material name="grey">
    <color rgba="0.2 0.2 0.2 0.0"/>
  </material>
  <material name="silver">
    <color rgba="0.9137254901960784 0.9137254901960784 0.8470588235294118 1.0"/>
  </material>
  <material name="orange">
    <color rgba="1.0 0.4235294117647059 0.0392156862745098 1.0"/>
  </material>
  <material name="brown">
    <color rgba="0.8705882352941177 0.8117647058823529 0.7647058823529411 1.0"/>
  </material>
  <material name="red">
    <color rgba="0.8 0.0 0.0 1.0"/>
  </material>
  <material name="white">
    <color rgba="1.0 1.0 1.0 1.0"/>
  </material>
  <ros2_control name="UnitreeSystem" type="system">
    <hardware>
      <plugin>hardware_unitree_sdk2/HardwareUnitree</plugin>
      <param name="domain">1</param>
      <param name="network_interface">lo</param>
      <param name="show_foot_force">true</param>
      <!-- UDP-only：不启动 DDS -->
      <param name="enable_dds">true</param>
      <param name="enable_udp">false</param>
      <!-- 本机验证：LowCmd 发到 127.0.0.1:9000；LowState 从本机 9001 收 -->
      <param name="udp_remote_ip">192.168.10.55</param>
      <param name="udp_remote_port">1978</param>
      <param name="udp_local_port">1978</param>
      <!-- 可选 -->
      <param name="udp_poll_timeout_ms">2</param>
      <param name="udp_state_timeout_ms">50</param>
    </hardware>
    <joint name="FR_hip_joint">
      <command_interface name="position"/>
      <command_interface name="velocity"/>
      <command_interface name="effort"/>
      <command_interface name="kp"/>
      <command_interface name="kd"/>
      <state_interface name="position"/>
      <state_interface name="velocity"/>
      <state_interface name="effort"/>
    </joint>
    <joint name="FR_thigh_joint">
      <command_interface name="position"/>
      <command_interface name="velocity"/>
      <command_interface name="effort"/>
      <command_interface name="kp"/>
      <command_interface name="kd"/>
      <state_interface name="position"/>
      <state_interface name="velocity"/>
      <state_interface name="effort"/>
    </joint>
    <joint name="FR_calf_joint">
      <command_interface name="position"/>
      <command_interface name="velocity"/>
      <command_interface name="effort"/>
      <command_interface name="kp"/>
      <command_interface name="kd"/>
      <state_interface name="position"/>
      <state_interface name="velocity"/>
      <state_interface name="effort"/>
    </joint>
    <joint name="FL_hip_joint">
      <command_interface name="position"/>
      <command_interface name="velocity"/>
      <command_interface name="effort"/>
      <command_interface name="kp"/>
      <command_interface name="kd"/>
      <state_interface name="position"/>
      <state_interface name="velocity"/>
      <state_interface name="effort"/>
    </joint>
    <joint name="FL_thigh_joint">
      <command_interface name="position"/>
      <command_interface name="velocity"/>
      <command_interface name="effort"/>
      <command_interface name="kp"/>
      <command_interface name="kd"/>
      <state_interface name="position"/>
      <state_interface name="velocity"/>
      <state_interface name="effort"/>
    </joint>
    <joint name="FL_calf_joint">
      <command_interface name="position"/>
      <command_interface name="velocity"/>
      <command_interface name="effort"/>
      <command_interface name="kp"/>
      <command_interface name="kd"/>
      <state_interface name="position"/>
      <state_interface name="velocity"/>
      <state_interface name="effort"/>
    </joint>
    <joint name="RR_hip_joint">
      <command_interface name="position"/>
      <command_interface name="velocity"/>
      <command_interface name="effort"/>
      <command_interface name="kp"/>
      <command_interface name="kd"/>
      <state_interface name="position"/>
      <state_interface name="velocity"/>
      <state_interface name="effort"/>
    </joint>
    <joint name="RR_thigh_joint">
      <command_interface name="position"/>
      <command_interface name="velocity"/>
      <command_interface name="effort"/>
      <command_interface name="kp"/>
      <command_interface name="kd"/>
      <state_interface name="position"/>
      <state_interface name="velocity"/>
      <state_interface name="effort"/>
    </joint>
    <joint name="RR_calf_joint">
      <command_interface name="position"/>
      <command_interface name="velocity"/>
      <command_interface name="effort"/>
      <command_interface name="kp"/>
      <command_interface name="kd"/>
      <state_interface name="position"/>
      <state_interface name="velocity"/>
      <state_interface name="effort"/>
    </joint>
    <joint name="RL_hip_joint">
      <command_interface name="position"/>
      <command_interface name="velocity"/>
      <command_interface name="effort"/>
      <command_interface name="kp"/>
      <command_interface name="kd"/>
      <state_interface name="position"/>
      <state_interface name="velocity"/>
      <state_interface name="effort"/>
    </joint>
    <joint name="RL_thigh_joint">
      <command_interface name="position"/>
      <command_interface name="velocity"/>
      <command_interface name="effort"/>
      <command_interface name="kp"/>
      <command_interface name="kd"/>
      <state_interface name="position"/>
      <state_interface name="velocity"/>
      <state_interface name="effort"/>
    </joint>
    <joint name="RL_calf_joint">
      <command_interface name="position"/>
      <command_interface name="velocity"/>
      <command_interface name="effort"/>
      <command_interface name="kp"/>
      <command_interface name="kd"/>
      <state_interface name="position"/>
      <state_interface name="velocity"/>
      <state_interface name="effort"/>
    </joint>
    <!-- 新增：补充FR_foot_joint接口（与transmission.xacro对应） -->
    <joint name="FR_foot_joint">
      <command_interface name="position"/>
      <command_interface name="velocity"/>
      <command_interface name="effort"/>
      <command_interface name="kp"/>
      <command_interface name="kd"/>
      <state_interface name="position"/>
      <state_interface name="velocity"/>
      <state_interface name="effort"/>
    </joint>
    <!-- 新增：补充FL_foot_joint接口（与transmission.xacro对应） -->
    <joint name="FL_foot_joint">
      <command_interface name="position"/>
      <command_interface name="velocity"/>
      <command_interface name="effort"/>
      <command_interface name="kp"/>
      <command_interface name="kd"/>
      <state_interface name="position"/>
      <state_interface name="velocity"/>
      <state_interface name="effort"/>
    </joint>
    <!-- 新增：补充RR_foot_joint接口（与transmission.xacro对应） -->
    <joint name="RR_foot_joint">
      <command_interface name="position"/>
      <command_interface name="velocity"/>
      <command_interface name="effort"/>
      <command_interface name="kp"/>
      <command_interface name="kd"/>
      <state_interface name="position"/>
      <state_interface name="velocity"/>
      <state_interface name="effort"/>
    </joint>
    <!-- 新增：补充RL_foot_joint接口（与transmission.xacro对应） -->
    <joint name="RL_foot_joint">
      <command_interface name="position"/>
      <command_interface name="velocity"/>
      <command_interface name="effort"/>
      <command_interface name="kp"/>
      <command_interface name="kd"/>
      <state_interface name="position"/>
      <state_interface name="velocity"/>
      <state_interface name="effort"/>
    </joint>
    <sensor name="imu_sensor">
      <state_interface name="orientation.w"/>
      <state_interface name="orientation.x"/>
      <state_interface name="orientation.y"/>
      <state_interface name="orientation.z"/>
      <state_interface name="angular_velocity.x"/>
      <state_interface name="angular_velocity.y"/>
      <state_interface name="angular_velocity.z"/>
      <state_interface name="linear_acceleration.x"/>
      <state_interface name="linear_acceleration.y"/>
      <state_interface name="linear_acceleration.z"/>
    </sensor>
    <sensor name="foot_force">
      <state_interface name="FR"/>
      <state_interface name="FL"/>
      <state_interface name="RR"/>
      <state_interface name="RL"/>
    </sensor>
    <sensor name="odometer">
      <state_interface name="position.x"/>
      <state_interface name="position.y"/>
      <state_interface name="position.z"/>
      <state_interface name="velocity.x"/>
      <state_interface name="velocity.y"/>
      <state_interface name="velocity.z"/>
    </sensor>
  </ros2_control>
  <!-- <xacro:stairs stairs="15" xpos="0" ypos="0" zpos="0" /> -->
  <!-- Rotor related joint and link is only for demonstrate location. -->
  <!-- Actually, the rotor will rotate and the joint is not fixed. Reduction ratio should be considered. -->
  <link name="base">
    <visual>
      <origin rpy="0 0 0" xyz="0 0 0"/>
      <geometry>
        <box size="0.001 0.001 0.001"/>
      </geometry>
    </visual>
  </link>
  <joint name="floating_base" type="fixed">
    <origin rpy="0 0 0" xyz="0 0 0"/>
    <parent link="base"/>
    <child link="trunk"/>
  </joint>
  <link name="trunk">
    <visual>
      <origin rpy="0 0 0" xyz="0 0 0"/>
      <geometry>
        <mesh filename="file:///home/zbs/Desktop/ros2_q/install/bw_description/share/bw_description/meshes/base.stl" scale="1 1 1"/>
      </geometry>
      <!-- <material name="orange"/> -->
    </visual>
    <collision>
      <origin rpy="0 0 0" xyz="0 0 0"/>
      <geometry>
        <box size="0.3262 0.225 0.125"/>
      </geometry>
    </collision>
    <inertial>
      <origin rpy="0 0 0" xyz="0.00027676 -0.0088849 -0.013996"/>
      <mass value="4.7"/>
      <inertia ixx="0.02140817" ixy="1.236e-05" ixz="1.48e-06" iyy="0.06703007" iyz="5.692e-05" izz="0.07949588"/>
    </inertial>
  </link>
  <joint name="imu_joint" type="fixed">
    <parent link="trunk"/>
    <child link="imu_link"/>
    <origin rpy="0 0 0" xyz="-0.01 0 0.01232"/>
  </joint>
  <link name="imu_link">
    <inertial>
      <mass value="0.001"/>
      <origin rpy="0 0 0" xyz="0 0 0"/>
      <inertia ixx="0.0001" ixy="0" ixz="0" iyy="0.0001" iyz="0" izz="0.0001"/>
    </inertial>
    <visual>
      <origin rpy="0 0 0" xyz="0 0 0"/>
      <geometry>
        <box size="0.001 0.001 0.001"/>
      </geometry>
      <!-- <material name="red"/> -->
    </visual>
    <collision>
      <origin rpy="0 0 0" xyz="0 0 0"/>
      <geometry>
        <box size=".001 .001 .001"/>
      </geometry>
    </collision>
  </link>
  <!-- 髋关节定义 -->
  <joint name="FR_hip_joint" type="revolute">
    <origin rpy="0 0 0" xyz="0.2265 -0.055 -0.015"/>
    <parent link="trunk"/>
    <child link="FR_hip"/>
    <axis xyz="1 0 0"/>
    <dynamics damping="0.1" friction="0.2"/>
    <limit effort="17.0" lower="-1.0472" upper="1.0472" velocity="20.1"/>
  </joint>
  <link name="FR_hip">
    <visual>
      <origin rpy="3.141592653589793 0 0" xyz="0 0 0"/>
      <geometry>
        <mesh filename="file:///home/zbs/Desktop/ros2_q/install/bw_description/share/bw_description/meshes/hip.stl" scale="1 1 1"/>
      </geometry>
    </visual>
    <collision>
      <origin rpy="1.5707963267948966 0 0" xyz="0 -0.044 0"/>
      <geometry>
        <cylinder length="0.13" radius="0.0395"/>
      </geometry>
    </collision>
    <inertial>
      <origin rpy="0 0 0" xyz="-0.0041211 -0.0051556 0.00012878"/>
      <mass value="0.5966"/>
      <inertia ixx="0.00047082" ixy="1.656e-05" ixz="-1.58e-06" iyy="0.00055549" iyz="-1.72e-06" izz="0.00058369"/>
    </inertial>
  </link>
  <!-- 大腿关节定义 -->
  <joint name="FR_thigh_joint" type="revolute">
    <origin rpy="0 0 0" xyz="0 -0.1025 0"/>
    <parent link="FR_hip"/>
    <child link="FR_thigh"/>
    <axis xyz="0 1 0"/>
    <dynamics damping="0.1" friction="0.2"/>
    <!-- 前腿 -->
    <limit effort="17.0" lower="-1.5708" upper="3.4907" velocity="20.1"/>
  </joint>
  <link name="FR_thigh">
    <visual>
      <origin rpy="0 0 0" xyz="0 0 0"/>
      <geometry>
        <mesh filename="file:///home/zbs/Desktop/ros2_q/install/bw_description/share/bw_description/meshes/thigh_mirror.stl" scale="1 1 1"/>
      </geometry>
    </visual>
    <collision>
      <origin rpy="0 1.5707963267948966 0" xyz="0 0.005 -0.08"/>
      <geometry>
        <box size="0.16 0.032 0.036"/>
      </geometry>
    </collision>
    <inertial>
      <origin rpy="0 0 0" xyz="-0.0019016 0.018616 -0.030116"/>
      <mass value="0.789"/>
      <inertia ixx="0.00402201" ixy="-2.047e-05" ixz="-1.747e-05" iyy="0.00396574" iyz="-0.0006155" izz="0.00054933"/>
    </inertial>
  </link>
  <!-- 小腿关节定义 -->
  <joint name="FR_calf_joint" type="revolute">
    <origin rpy="0 0 0" xyz="0 0.004 -0.16"/>
    <parent link="FR_thigh"/>
    <child link="FR_calf"/>
    <axis xyz="0 1 0"/>
    <dynamics damping="0.1" friction="0.2"/>
    <limit effort="34.0" lower="-2.68" upper="-0.88" velocity="12.07"/>
  </joint>
  <link name="FR_calf">
    <visual>
      <origin rpy="0 0 0" xyz="0 0 0"/>
      <geometry>
        <mesh filename="file:///home/zbs/Desktop/ros2_q/install/bw_description/share/bw_description/meshes/calf_mirror.stl" scale="1 1 1"/>
      </geometry>
    </visual>
    <collision>
      <origin rpy="0 1.5707963267948966 0" xyz="0 0 -0.06249999999999999"/>
      <geometry>
        <box size="0.175 0.018 0.026"/>
      </geometry>
    </collision>
    <inertial>
      <origin rpy="0 0 0" xyz="-0.000765487060335857 -0.0183577890363815 -0.154926754684192"/>
      <mass value="0.377"/>
      <inertia ixx="0.00098633" ixy="4.02e-06" ixz="1.053e-05" iyy="0.00097543" iyz="-0.00013167" izz="0.00017669"/>
    </inertial>
  </link>
  <transmission name="FR_hip_tran">
    <type>transmission_interface/SimpleTransmission</type>
    <joint name="FR_hip_joint">
      <hardwareInterface>hardware_interface/EffortJointInterface</hardwareInterface>
    </joint>
    <actuator name="FR_hip_motor">
      <hardwareInterface>hardware_interface/EffortJointInterface</hardwareInterface>
      <mechanicalReduction>1</mechanicalReduction>
    </actuator>
  </transmission>
  <transmission name="FR_thigh_tran">
    <type>transmission_interface/SimpleTransmission</type>
    <joint name="FR_thigh_joint">
      <hardwareInterface>hardware_interface/EffortJointInterface</hardwareInterface>
    </joint>
    <actuator name="FR_thigh_motor">
      <hardwareInterface>hardware_interface/EffortJointInterface</hardwareInterface>
      <mechanicalReduction>1</mechanicalReduction>
    </actuator>
  </transmission>
  <transmission name="FR_calf_tran">
    <type>transmission_interface/SimpleTransmission</type>
    <joint name="FR_calf_joint">
      <hardwareInterface>hardware_interface/EffortJointInterface</hardwareInterface>
    </joint>
    <actuator name="FR_calf_motor">
      <hardwareInterface>hardware_interface/EffortJointInterface</hardwareInterface>
      <mechanicalReduction>1</mechanicalReduction>
    </actuator>
  </transmission>
  <!-- 髋关节定义 -->
  <joint name="FL_hip_joint" type="revolute">
    <origin rpy="0 0 0" xyz="0.2265 0.055 -0.015"/>
    <parent link="trunk"/>
    <child link="FL_hip"/>
    <axis xyz="1 0 0"/>
    <dynamics damping="0.1" friction="0.2"/>
    <limit effort="17.0" lower="-1.0472" upper="1.0472" velocity="20.1"/>
  </joint>
  <link name="FL_hip">
    <visual>
      <origin rpy="0 0 0" xyz="0 0 0"/>
      <geometry>
        <mesh filename="file:///home/zbs/Desktop/ros2_q/install/bw_description/share/bw_description/meshes/hip.stl" scale="1 1 1"/>
      </geometry>
    </visual>
    <collision>
      <origin rpy="1.5707963267948966 0 0" xyz="0 0.044 0"/>
      <geometry>
        <cylinder length="0.13" radius="0.0395"/>
      </geometry>
    </collision>
    <inertial>
      <origin rpy="0 0 0" xyz="-0.0041211 0.0051556 0.00012878"/>
      <mass value="0.5966"/>
      <inertia ixx="0.00047082" ixy="-1.656e-05" ixz="-1.58e-06" iyy="0.00055549" iyz="1.72e-06" izz="0.00058369"/>
    </inertial>
  </link>
  <!-- 大腿关节定义 -->
  <joint name="FL_thigh_joint" type="revolute">
    <origin rpy="0 0 0" xyz="0 0.1025 0"/>
    <parent link="FL_hip"/>
    <child link="FL_thigh"/>
    <axis xyz="0 1 0"/>
    <dynamics damping="0.1" friction="0.2"/>
    <!-- 前腿 -->
    <limit effort="17.0" lower="-1.5708" upper="3.4907" velocity="20.1"/>
  </joint>
  <link name="FL_thigh">
    <visual>
      <origin rpy="0 0 0" xyz="0 0 0"/>
      <geometry>
        <mesh filename="file:///home/zbs/Desktop/ros2_q/install/bw_description/share/bw_description/meshes/thigh.stl" scale="1 1 1"/>
      </geometry>
    </visual>
    <collision>
      <origin rpy="0 1.5707963267948966 0" xyz="0 -0.005 -0.08"/>
      <geometry>
        <box size="0.16 0.032 0.036"/>
      </geometry>
    </collision>
    <inertial>
      <origin rpy="0 0 0" xyz="-0.0019016 -0.018616 -0.030116"/>
      <mass value="0.789"/>
      <inertia ixx="0.00402201" ixy="2.047e-05" ixz="-1.747e-05" iyy="0.00396574" iyz="0.0006155" izz="0.00054933"/>
    </inertial>
  </link>
  <!-- 小腿关节定义 -->
  <joint name="FL_calf_joint" type="revolute">
    <origin rpy="0 0 0" xyz="0 -0.004 -0.16"/>
    <parent link="FL_thigh"/>
    <child link="FL_calf"/>
    <axis xyz="0 1 0"/>
    <dynamics damping="0.1" friction="0.2"/>
    <limit effort="34.0" lower="-2.68" upper="-0.88" velocity="12.07"/>
  </joint>
  <link name="FL_calf">
    <visual>
      <origin rpy="0 0 0" xyz="0 0 0"/>
      <geometry>
        <mesh filename="file:///home/zbs/Desktop/ros2_q/install/bw_description/share/bw_description/meshes/calf.stl" scale="1 1 1"/>
      </geometry>
    </visual>
    <collision>
      <origin rpy="0 1.5707963267948966 0" xyz="0 0 -0.06249999999999999"/>
      <geometry>
        <box size="0.175 0.018 0.026"/>
      </geometry>
    </collision>
    <inertial>
      <origin rpy="0 0 0" xyz="-0.000765487060335857 0.0183577890363815 -0.154926754684192"/>
      <mass value="0.377"/>
      <inertia ixx="0.00098633" ixy="-4.02e-06" ixz="1.053e-05" iyy="0.00097543" iyz="0.00013167" izz="0.00017669"/>
    </inertial>
  </link>
  <transmission name="FL_hip_tran">
    <type>transmission_interface/SimpleTransmission</type>
    <joint name="FL_hip_joint">
      <hardwareInterface>hardware_interface/EffortJointInterface</hardwareInterface>
    </joint>
    <actuator name="FL_hip_motor">
      <hardwareInterface>hardware_interface/EffortJointInterface</hardwareInterface>
      <mechanicalReduction>1</mechanicalReduction>
    </actuator>
  </transmission>
  <transmission name="FL_thigh_tran">
    <type>transmission_interface/SimpleTransmission</type>
    <joint name="FL_thigh_joint">
      <hardwareInterface>hardware_interface/EffortJointInterface</hardwareInterface>
    </joint>
    <actuator name="FL_thigh_motor">
      <hardwareInterface>hardware_interface/EffortJointInterface</hardwareInterface>
      <mechanicalReduction>1</mechanicalReduction>
    </actuator>
  </transmission>
  <transmission name="FL_calf_tran">
    <type>transmission_interface/SimpleTransmission</type>
    <joint name="FL_calf_joint">
      <hardwareInterface>hardware_interface/EffortJointInterface</hardwareInterface>
    </joint>
    <actuator name="FL_calf_motor">
      <hardwareInterface>hardware_interface/EffortJointInterface</hardwareInterface>
      <mechanicalReduction>1</mechanicalReduction>
    </actuator>
  </transmission>
  <!-- 髋关节定义 -->
  <joint name="RR_hip_joint" type="revolute">
    <origin rpy="0 0 0" xyz="-0.2265 -0.055 -0.015"/>
    <parent link="trunk"/>
    <child link="RR_hip"/>
    <axis xyz="1 0 0"/>
    <dynamics damping="0.1" friction="0.2"/>
    <limit effort="17.0" lower="-1.0472" upper="1.0472" velocity="20.1"/>
  </joint>
  <link name="RR_hip">
    <visual>
      <origin rpy="3.141592653589793 3.141592653589793 0" xyz="0 0 0"/>
      <geometry>
        <mesh filename="file:///home/zbs/Desktop/ros2_q/install/bw_description/share/bw_description/meshes/hip.stl" scale="1 1 1"/>
      </geometry>
    </visual>
    <collision>
      <origin rpy="1.5707963267948966 0 0" xyz="0 -0.044 0"/>
      <geometry>
        <cylinder length="0.13" radius="0.0395"/>
      </geometry>
    </collision>
    <inertial>
      <origin rpy="0 0 0" xyz="0.0041211 -0.0051556 0.00012878"/>
      <mass value="0.5966"/>
      <inertia ixx="0.00047082" ixy="-1.656e-05" ixz="1.58e-06" iyy="0.00055549" iyz="-1.72e-06" izz="0.00058369"/>
    </inertial>
  </link>
  <!-- 大腿关节定义 -->
  <joint name="RR_thigh_joint" type="revolute">
    <origin rpy="0 0 0" xyz="0 -0.1025 0"/>
    <parent link="RR_hip"/>
    <child link="RR_thigh"/>
    <axis xyz="0 1 0"/>
    <dynamics damping="0.1" friction="0.2"/>
    <!-- 后腿 -->
    <limit effort="17.0" lower="-0.5236" upper="4.5379" velocity="20.1"/>
  </joint>
  <link name="RR_thigh">
    <visual>
      <origin rpy="0 0 0" xyz="0 0 0"/>
      <geometry>
        <mesh filename="file:///home/zbs/Desktop/ros2_q/install/bw_description/share/bw_description/meshes/thigh_mirror.stl" scale="1 1 1"/>
      </geometry>
    </visual>
    <collision>
      <origin rpy="0 1.5707963267948966 0" xyz="0 0.005 -0.08"/>
      <geometry>
        <box size="0.16 0.032 0.036"/>
      </geometry>
    </collision>
    <inertial>
      <origin rpy="0 0 0" xyz="0.0019016 0.018616 -0.030116"/>
      <mass value="0.789"/>
      <inertia ixx="0.00402201" ixy="2.047e-05" ixz="1.747e-05" iyy="0.00396574" iyz="-0.0006155" izz="0.00054933"/>
    </inertial>
  </link>
  <!-- 小腿关节定义 -->
  <joint name="RR_calf_joint" type="revolute">
    <origin rpy="0 0 0" xyz="0 0.004 -0.16"/>
    <parent link="RR_thigh"/>
    <child link="RR_calf"/>
    <axis xyz="0 1 0"/>
    <dynamics damping="0.1" friction="0.2"/>
    <limit effort="34.0" lower="-2.68" upper="-0.88" velocity="12.07"/>
  </joint>
  <link name="RR_calf">
    <visual>
      <origin rpy="0 0 0" xyz="0 0 0"/>
      <geometry>
        <mesh filename="file:///home/zbs/Desktop/ros2_q/install/bw_description/share/bw_description/meshes/calf_mirror.stl" scale="1 1 1"/>
      </geometry>
    </visual>
    <collision>
      <origin rpy="0 1.5707963267948966 0" xyz="0 0 -0.06249999999999999"/>
      <geometry>
        <box size="0.175 0.018 0.026"/>
      </geometry>
    </collision>
    <inertial>
      <origin rpy="0 0 0" xyz="0.000765487060335857 -0.0183577890363815 -0.154926754684192"/>
      <mass value="0.377"/>
      <inertia ixx="0.00098633" ixy="-4.02e-06" ixz="-1.053e-05" iyy="0.00097543" iyz="-0.00013167" izz="0.00017669"/>
    </inertial>
  </link>
  <transmission name="RR_hip_tran">
    <type>transmission_interface/SimpleTransmission</type>
    <joint name="RR_hip_joint">
      <hardwareInterface>hardware_interface/EffortJointInterface</hardwareInterface>
    </joint>
    <actuator name="RR_hip_motor">
      <hardwareInterface>hardware_interface/EffortJointInterface</hardwareInterface>
      <mechanicalReduction>1</mechanicalReduction>
    </actuator>
  </transmission>
  <transmission name="RR_thigh_tran">
    <type>transmission_interface/SimpleTransmission</type>
    <joint name="RR_thigh_joint">
      <hardwareInterface>hardware_interface/EffortJointInterface</hardwareInterface>
    </joint>
    <actuator name="RR_thigh_motor">
      <hardwareInterface>hardware_interface/EffortJointInterface</hardwareInterface>
      <mechanicalReduction>1</mechanicalReduction>
    </actuator>
  </transmission>
  <transmission name="RR_calf_tran">
    <type>transmission_interface/SimpleTransmission</type>
    <joint name="RR_calf_joint">
      <hardwareInterface>hardware_interface/EffortJointInterface</hardwareInterface>
    </joint>
    <actuator name="RR_calf_motor">
      <hardwareInterface>hardware_interface/EffortJointInterface</hardwareInterface>
      <mechanicalReduction>1</mechanicalReduction>
    </actuator>
  </transmission>
  <!-- 髋关节定义 -->
  <joint name="RL_hip_joint" type="revolute">
    <origin rpy="0 0 0" xyz="-0.2265 0.055 -0.015"/>
    <parent link="trunk"/>
    <child link="RL_hip"/>
    <axis xyz="1 0 0"/>
    <dynamics damping="0.1" friction="0.2"/>
    <limit effort="17.0" lower="-1.0472" upper="1.0472" velocity="20.1"/>
  </joint>
  <link name="RL_hip">
    <visual>
      <origin rpy="0 3.141592653589793 0" xyz="0 0 0"/>
      <geometry>
        <mesh filename="file:///home/zbs/Desktop/ros2_q/install/bw_description/share/bw_description/meshes/hip.stl" scale="1 1 1"/>
      </geometry>
    </visual>
    <collision>
      <origin rpy="1.5707963267948966 0 0" xyz="0 0.044 0"/>
      <geometry>
        <cylinder length="0.13" radius="0.0395"/>
      </geometry>
    </collision>
    <inertial>
      <origin rpy="0 0 0" xyz="0.0041211 0.0051556 0.00012878"/>
      <mass value="0.5966"/>
      <inertia ixx="0.00047082" ixy="1.656e-05" ixz="1.58e-06" iyy="0.00055549" iyz="1.72e-06" izz="0.00058369"/>
    </inertial>
  </link>
  <!-- 大腿关节定义 -->
  <joint name="RL_thigh_joint" type="revolute">
    <origin rpy="0 0 0" xyz="0 0.1025 0"/>
    <parent link="RL_hip"/>
    <child link="RL_thigh"/>
    <axis xyz="0 1 0"/>
    <dynamics damping="0.1" friction="0.2"/>
    <!-- 后腿 -->
    <limit effort="17.0" lower="-0.5236" upper="4.5379" velocity="20.1"/>
  </joint>
  <link name="RL_thigh">
    <visual>
      <origin rpy="0 0 0" xyz="0 0 0"/>
      <geometry>
        <mesh filename="file:///home/zbs/Desktop/ros2_q/install/bw_description/share/bw_description/meshes/thigh.stl" scale="1 1 1"/>
      </geometry>
    </visual>
    <collision>
      <origin rpy="0 1.5707963267948966 0" xyz="0 -0.005 -0.08"/>
      <geometry>
        <box size="0.16 0.032 0.036"/>
      </geometry>
    </collision>
    <inertial>
      <origin rpy="0 0 0" xyz="0.0019016 -0.018616 -0.030116"/>
      <mass value="0.789"/>
      <inertia ixx="0.00402201" ixy="-2.047e-05" ixz="1.747e-05" iyy="0.00396574" iyz="0.0006155" izz="0.00054933"/>
    </inertial>
  </link>
  <!-- 小腿关节定义 -->
  <joint name="RL_calf_joint" type="revolute">
    <origin rpy="0 0 0" xyz="0 -0.004 -0.16"/>
    <parent link="RL_thigh"/>
    <child link="RL_calf"/>
    <axis xyz="0 1 0"/>
    <dynamics damping="0.1" friction="0.2"/>
    <limit effort="34.0" lower="-2.68" upper="-0.88" velocity="12.07"/>
  </joint>
  <link name="RL_calf">
    <visual>
      <origin rpy="0 0 0" xyz="0 0 0"/>
      <geometry>
        <mesh filename="file:///home/zbs/Desktop/ros2_q/install/bw_description/share/bw_description/meshes/calf.stl" scale="1 1 1"/>
      </geometry>
    </visual>
    <collision>
      <origin rpy="0 1.5707963267948966 0" xyz="0 0 -0.06249999999999999"/>
      <geometry>
        <box size="0.175 0.018 0.026"/>
      </geometry>
    </collision>
    <inertial>
      <origin rpy="0 0 0" xyz="0.000765487060335857 0.0183577890363815 -0.154926754684192"/>
      <mass value="0.377"/>
      <inertia ixx="0.00098633" ixy="4.02e-06" ixz="-1.053e-05" iyy="0.00097543" iyz="0.00013167" izz="0.00017669"/>
    </inertial>
  </link>
  <transmission name="RL_hip_tran">
    <type>transmission_interface/SimpleTransmission</type>
    <joint name="RL_hip_joint">
      <hardwareInterface>hardware_interface/EffortJointInterface</hardwareInterface>
    </joint>
    <actuator name="RL_hip_motor">
      <hardwareInterface>hardware_interface/EffortJointInterface</hardwareInterface>
      <mechanicalReduction>1</mechanicalReduction>
    </actuator>
  </transmission>
  <transmission name="RL_thigh_tran">
    <type>transmission_interface/SimpleTransmission</type>
    <joint name="RL_thigh_joint">
      <hardwareInterface>hardware_interface/EffortJointInterface</hardwareInterface>
    </joint>
    <actuator name="RL_thigh_motor">
      <hardwareInterface>hardware_interface/EffortJointInterface</hardwareInterface>
      <mechanicalReduction>1</mechanicalReduction>
    </actuator>
  </transmission>
  <transmission name="RL_calf_tran">
    <type>transmission_interface/SimpleTransmission</type>
    <joint name="RL_calf_joint">
      <hardwareInterface>hardware_interface/EffortJointInterface</hardwareInterface>
    </joint>
    <actuator name="RL_calf_motor">
      <hardwareInterface>hardware_interface/EffortJointInterface</hardwareInterface>
      <mechanicalReduction>1</mechanicalReduction>
    </actuator>
  </transmission>
  <!-- 足部关节定义 - 已修改为continuous类型 -->
  <joint name="FR_foot_joint" type="continuous">
    <origin rpy="0 0 0" xyz="0 -0.061 -0.18"/>
    <parent link="FR_calf"/>
    <child link="FR_foot"/>
    <axis xyz="0 1 0"/>
    <dynamics damping="0.1" friction="0.2"/>
    <limit effort="12.0" velocity="18.1"/>
  </joint>
  <!-- 0.0515-->
  <link name="FR_foot">
    <visual>
      <origin rpy="0 0 0" xyz="0 0 0"/>
      <geometry>
        <mesh filename="file:///home/zbs/Desktop/ros2_q/install/bw_description/share/bw_description/meshes/wheel_mirror.stl"/>
      </geometry>
      <material name="">
        <color rgba="1 1 1 1"/>
      </material>
    </visual>
    <collision>
      <origin rpy="1.5707963267948966 0 0" xyz="0 0.010000000000000002 0"/>
      <geometry>
        <cylinder length="0.035" radius="0.099"/>
      </geometry>
    </collision>
    <inertial>
      <origin rpy="0 0 0" xyz="3.61016876218034e-05 0.0115832620181727 -8.02701045317655e-05"/>
      <mass value="0.6959"/>
      <inertia ixx="0.00216437" ixy="-2.3e-07" ixz="1.29e-06" iyy="0.0041558" iyz="1e-07" izz="0.00216126"/>
    </inertial>
  </link>
  <transmission name="FR_foot_tran">
    <type>transmission_interface/SimpleTransmission</type>
    <joint name="FR_foot_joint">
      <hardwareInterface>hardware_interface/EffortJointInterface</hardwareInterface>
    </joint>
    <actuator name="FR_foot_motor">
      <hardwareInterface>hardware_interface/EffortJointInterface</hardwareInterface>
      <mechanicalReduction>1</mechanicalReduction>
    </actuator>
  </transmission>
  <!-- 足部关节定义 - 已修改为continuous类型 -->
  <joint name="FL_foot_joint" type="continuous">
    <origin rpy="0 0 0" xyz="0 0.061 -0.18"/>
    <parent link="FL_calf"/>
    <child link="FL_foot"/>
    <axis xyz="0 1 0"/>
    <dynamics damping="0.1" friction="0.2"/>
    <limit effort="12.0" velocity="18.1"/>
  </joint>
  <!-- 0.0515-->
  <link name="FL_foot">
    <visual>
      <origin rpy="0 0 0" xyz="0 0 0"/>
      <geometry>
        <mesh filename="file:///home/zbs/Desktop/ros2_q/install/bw_description/share/bw_description/meshes/wheel.stl"/>
      </geometry>
      <material name="">
        <color rgba="1 1 1 1"/>
      </material>
    </visual>
    <collision>
      <origin rpy="1.5707963267948966 0 0" xyz="0 -0.010000000000000002 0"/>
      <geometry>
        <cylinder length="0.035" radius="0.099"/>
      </geometry>
    </collision>
    <inertial>
      <origin rpy="0 0 0" xyz="3.61016876218034e-05 -0.0115832620181727 -8.02701045317655e-05"/>
      <mass value="0.6959"/>
      <inertia ixx="0.00216437" ixy="2.3e-07" ixz="1.29e-06" iyy="0.0041558" iyz="-1e-07" izz="0.00216126"/>
    </inertial>
  </link>
  <transmission name="FL_foot_tran">
    <type>transmission_interface/SimpleTransmission</type>
    <joint name="FL_foot_joint">
      <hardwareInterface>hardware_interface/EffortJointInterface</hardwareInterface>
    </joint>
    <actuator name="FL_foot_motor">
      <hardwareInterface>hardware_interface/EffortJointInterface</hardwareInterface>
      <mechanicalReduction>1</mechanicalReduction>
    </actuator>
  </transmission>
  <!-- 足部关节定义 - 已修改为continuous类型 -->
  <joint name="RR_foot_joint" type="continuous">
    <origin rpy="0 0 0" xyz="0 -0.061 -0.18"/>
    <parent link="RR_calf"/>
    <child link="RR_foot"/>
    <axis xyz="0 1 0"/>
    <dynamics damping="0.1" friction="0.2"/>
    <limit effort="12.0" velocity="18.1"/>
  </joint>
  <!-- 0.0515-->
  <link name="RR_foot">
    <visual>
      <origin rpy="0 0 0" xyz="0 0 0"/>
      <geometry>
        <mesh filename="file:///home/zbs/Desktop/ros2_q/install/bw_description/share/bw_description/meshes/wheel_mirror.stl"/>
      </geometry>
      <material name="">
        <color rgba="1 1 1 1"/>
      </material>
    </visual>
    <collision>
      <origin rpy="1.5707963267948966 0 0" xyz="0 0.010000000000000002 0"/>
      <geometry>
        <cylinder length="0.035" radius="0.099"/>
      </geometry>
    </collision>
    <inertial>
      <origin rpy="0 0 0" xyz="-3.61016876218034e-05 0.0115832620181727 -8.02701045317655e-05"/>
      <mass value="0.6959"/>
      <inertia ixx="0.00216437" ixy="2.3e-07" ixz="-1.29e-06" iyy="0.0041558" iyz="1e-07" izz="0.00216126"/>
    </inertial>
  </link>
  <transmission name="RR_foot_tran">
    <type>transmission_interface/SimpleTransmission</type>
    <joint name="RR_foot_joint">
      <hardwareInterface>hardware_interface/EffortJointInterface</hardwareInterface>
    </joint>
    <actuator name="RR_foot_motor">
      <hardwareInterface>hardware_interface/EffortJointInterface</hardwareInterface>
      <mechanicalReduction>1</mechanicalReduction>
    </actuator>
  </transmission>
  <!-- 足部关节定义 - 已修改为continuous类型 -->
  <joint name="RL_foot_joint" type="continuous">
    <origin rpy="0 0 0" xyz="0 0.061 -0.18"/>
    <parent link="RL_calf"/>
    <child link="RL_foot"/>
    <axis xyz="0 1 0"/>
    <dynamics damping="0.1" friction="0.2"/>
    <limit effort="12.0" velocity="18.1"/>
  </joint>
  <!-- 0.0515-->
  <link name="RL_foot">
    <visual>
      <origin rpy="0 0 0" xyz="0 0 0"/>
      <geometry>
        <mesh filename="file:///home/zbs/Desktop/ros2_q/install/bw_description/share/bw_description/meshes/wheel.stl"/>
      </geometry>
      <material name="">
        <color rgba="1 1 1 1"/>
      </material>
    </visual>
    <collision>
      <origin rpy="1.5707963267948966 0 0" xyz="0 -0.010000000000000002 0"/>
      <geometry>
        <cylinder length="0.035" radius="0.099"/>
      </geometry>
    </collision>
    <inertial>
      <origin rpy="0 0 0" xyz="-3.61016876218034e-05 -0.0115832620181727 -8.02701045317655e-05"/>
      <mass value="0.6959"/>
      <inertia ixx="0.00216437" ixy="-2.3e-07" ixz="-1.29e-06" iyy="0.0041558" iyz="-1e-07" izz="0.00216126"/>
    </inertial>
  </link>
  <transmission name="RL_foot_tran">
    <type>transmission_interface/SimpleTransmission</type>
    <joint name="RL_foot_joint">
      <hardwareInterface>hardware_interface/EffortJointInterface</hardwareInterface>
    </joint>
    <actuator name="RL_foot_motor">
      <hardwareInterface>hardware_interface/EffortJointInterface</hardwareInterface>
      <mechanicalReduction>1</mechanicalReduction>
    </actuator>
  </transmission>
</robot>
